Workbook

Sheet Hướng dẫn
A1: SỔ QUẢN LÝ DÂN CƯ – TỔ 23
A3: Cách dùng
A4: • Mỗi người là MỘT dòng trong sheet "Cư dân". Mỗi hộ là MỘT dòng trong sheet "Hộ gia đình".
A5: • Người và hộ nối với nhau bằng cột "Mã hộ". Địa chỉ chỉ ghi một lần ở sheet "Hộ gia đình"; sheet "Cư dân" tự lấy theo.
A6: • Cột nền XÁM là công thức tự tính (Tuổi, Nhóm tuổi, Địa chỉ, Số nhân khẩu, Chủ hộ): không gõ vào.
A7: • Cột nền TRẮNG là ô nhập. Các cột có mũi tên (Giới tính, Quan hệ, Cử tri, Tình trạng…) chọn từ danh sách.
A8: • Không xóa người đã chuyển đi hay đã mất: đổi "Tình trạng" để giữ lịch sử. Thống kê chỉ đếm người "Đang ở".
A9: • Cột "Cần kiểm tra" (nền vàng) ghi các điểm không khớp giữa các danh sách cũ. Kiểm tra xong thì xóa nội dung ô.
A11: Khi có biến động
A12: 1. Sinh / chuyển đến: thêm một dòng ở cuối sheet "Cư dân" với mã mới (CD tiếp theo) và Mã hộ.
A13: 2. Hộ mới: thêm một dòng ở cuối sheet "Hộ gia đình" với mã mới (H tiếp theo), rồi thêm các thành viên.
A14: 3. Chuyển đi / mất: đổi "Tình trạng" của người đó.
... A26: Bổ sung 2 người từ danh sách người cao tuổi (ĐỔI_TÊN_nct.xlsx) ở 6 ngõ 15 Tạ Quang Bửu. Những người ở Đê Tô Hoàng và Ngõ Chùa Liên Phái trong danh sách đó không thuộc tổ nên không được thêm.

Sheet Thống kê
A1: THỐNG KÊ (chỉ tính người "Đang ở")
A3: Số hộ có người đang ở | B3: =COUNTIF('Hộ gia đình'!$D$2:$D$2000,">0") -> 160
A4: Tổng số nhân khẩu | B4: =COUNTIFS('Cư dân'!$O$2:$O$2000,"Đang ở") -> 672
A5: Nam | B5: =COUNTIFS('Cư dân'!$O$2:$O$2000,"Đang ở",'Cư dân'!$D$2:$D$2000,"Nam") -> 173
A6: Nữ | B6: =COUNTIFS('Cư dân'!$O$2:$O$2000,"Đang ở",'Cư dân'!$D$2:$D$2000,"Nữ") -> 186
A7: Chưa ghi giới tính | B7: =COUNTIFS('Cư dân'!$O$2:$O$2000,"Đang ở",'Cư dân'!$D$2:$D$2000,"") -> 313
A8: Cử tri | B8: =COUNTIFS('Cư dân'!$O$2:$O$2000,"Đang ở",'Cư dân'!$N$2:$N$2000,"Có") -> 326
A10: Theo nhóm tuổi
A11: Trẻ em | B11: =COUNTIFS('Cư dân'!$O$2:$O$2000,"Đang ở",'Cư dân'!$H$2:$H$2000,"Trẻ em") -> 9
A12: Học sinh / Sinh viên | B12: =COUNTIFS('Cư dân'!$O$2:$O$2000,"Đang ở",'Cư dân'!$H$2:$H$2000,"Học sinh / Sinh viên") -> 172
A13: Đang đi làm | B13: =COUNTIFS('Cư dân'!$O$2:$O$2000,"Đang ở",'Cư dân'!$H$2:$H$2000,"Đang đi làm") -> 351
A14: Nghỉ hưu | B14: =COUNTIFS('Cư dân'!$O$2:$O$2000,"Đang ở",'Cư dân'!$H$2:$H$2000,"Nghỉ hưu") -> 129
A15: Thiếu thông tin | B15: =COUNTIFS('Cư dân'!$O$2:$O$2000,"Đang ở",'Cư dân'!$H$2:$H$2000,"Thiếu thông tin") -> 11
A17: Mừng thọ năm nay (theo tuổi)
A18: 70 tuổi | B18: =COUNTIFS('Cư dân'!$O$2:$O$2000,"Đang ở",'Cư dân'!$G$2:$G$2000,70) -> 4
A19: 75 tuổi | B19: =COUNTIFS('Cư dân'!$O$2:$O$2000,"Đang ở",'Cư dân'!$G$2:$G$2000,75) -> 4
A20: 80 tuổi | B20: =COUNTIFS('Cư dân'!$O$2:$O$2000,"Đang ở",'Cư dân'!$G$2:$G$2000,80) -> 2
A21: 85 tuổi | B21: =COUNTIFS('Cư dân'!$O$2:$O$2000,"Đang ở",'Cư dân'!$G$2:$G$2000,85) -> 1
A22: 90 tuổi | B22: =COUNTIFS('Cư dân'!$O$2:$O$2000,"Đang ở",'Cư dân'!$G$2:$G$2000,90) -> 2
A23: 95 tuổi | B23: =COUNTIFS('Cư dân'!$O$2:$O$2000,"Đang ở",'Cư dân'!$G$2:$G$2000,95) -> 1
A24: Từ 100 tuổi | B24: =COUNTIFS('Cư dân'!$O$2:$O$2000,"Đang ở",'Cư dân'!$G$2:$G$2000,">=100") -> 0
A26: Nam trong độ tuổi nghĩa vụ quân sự (18–27) | B26: =COUNTIFS('Cư dân'!$O$2:$O$2000,"Đang ở",'Cư dân'!$D$2:$D$2000,"Nam",'Cư dân'!$G$2:$G$2000,">=18",'Cư dân'!$G$2:$G$2000,"<=27") -> 37
A28: Tình trạng khác
A29: Tạm vắng | B29: =COUNTIF('Cư dân'!$O$2:$O$2000,"Tạm vắng") -> 3
A30: Đã chuyển đi | B30: =COUNTIF('Cư dân'!$O$2:$O$2000,"Đã chuyển đi") -> 1
A31: Đã mất | B31: =COUNTIF('Cư dân'!$O$2:$O$2000,"Đã mất") -> 3
A32: Dòng còn "Cần kiểm tra" | B32: =COUNTIF('Cư dân'!$R$2:$R$2000,"?*") -> 132
A34: Muốn có danh sách (mừng thọ, nghĩa vụ quân sự…): vào sheet "Cư dân", dùng bộ lọc ở cột Tuổi / Giới tính / Tình trạng.

Sheet Hộ gia đình
A1: Mã hộ | B1: Địa chỉ | C1: Chủ hộ | D1: Số nhân khẩu (đang ở) | E1: Ghi chú | F1: Cần kiểm tra
A2: H001 | B2: 40 Lê Thanh Nghị | C2: =IFERROR(INDEX('Cư dân'!$C$2:$C$2000,MATCH(1,INDEX(('Cư dân'!$B$2:$B$2000=A2)*('Cư dân'!$I$2:$I$2000="Chủ hộ"),0),0)),"") -> Phạm Thị Ngân | D2: =COUNTIFS('Cư dân'!$B$2:$B$2000,A2,'Cư dân'!$O$2:$O$2000,"Đang ở") -> 10
A3: H002 | B3: 42 Lê Thanh Nghị | C3: =IFERROR(INDEX('Cư dân'!$C$2:$C$2000,MATCH(1,INDEX(('Cư dân'!$B$2:$B$2000=A3)*('Cư dân'!$I$2:$I$2000="Chủ hộ"),0),0)),"") -> Tạ Đình Tuấn | D3: =COUNTIFS('Cư dân'!$B$2:$B$2000,A3,'Cư dân'!$O$2:$O$2000,"Đang ở") -> 5
A4: H003 | B4: 44 Lê Thanh Nghị | C4: =IFERROR(INDEX('Cư dân'!$C$2:$C$2000,MATCH(1,INDEX(('Cư dân'!$B$2:$B$2000=A4)*('Cư dân'!$I$2:$I$2000="Chủ hộ"),0),0)),"") -> Lê Thị Hồng | D4: =COUNTIFS('Cư dân'!$B$2:$B$2000,A4,'Cư dân'!$O$2:$O$2000,"Đang ở") -> 1
A5: H004 | B5: 44 Lê Thanh Nghị | C5: =IFERROR(INDEX('Cư dân'!$C$2:$C$2000,MATCH(1,INDEX(('Cư dân'!$B$2:$B$2000=A5)*('Cư dân'!$I$2:$I$2000="Chủ hộ"),0),0)),"") -> Nguyễn Thị Bích Huệ | D5: =COUNTIFS('Cư dân'!$B$2:$B$2000,A5,'Cư dân'!$O$2:$O$2000,"Đang ở") -> 1
A6: H005 | B6: 44 Lê Thanh Nghị | C6: =IFERROR(INDEX('Cư dân'!$C$2:$C$2000,MATCH(1,INDEX(('Cư dân'!$B$2:$B$2000=A6)*('Cư dân'!$I$2:$I$2000="Chủ hộ"),0),0)),"") -> Nguyễn Thị Thu Hằng | D6: =COUNTIFS('Cư dân'!$B$2:$B$2000,A6,'Cư dân'!$O$2:$O$2000,"Đang ở") -> 4
A7: H006 | B7: 46 Lê Thanh Nghị | C7: =IFERROR(INDEX('Cư dân'!$C$2:$C$2000,MATCH(1,INDEX(('Cư dân'!$B$2:$B$2000=A7)*('Cư dân'!$I$2:$I$2000="Chủ hộ"),0),0)),"") -> Phạm Văn Khôi | D7: =COUNTIFS('Cư dân'!$B$2:$B$2000,A7,'Cư dân'!$O$2:$O$2000,"Đang ở") -> 8
A8: H007 | B8: 48 Lê Thanh Nghị | C8: =IFERROR(INDEX('Cư dân'!$C$2:$C$2000,MATCH(1,INDEX(('Cư dân'!$B$2:$B$2000=A8)*('Cư dân'!$I$2:$I$2000="Chủ hộ"),0),0)),"") -> Quách Thị Hương | D8: =COUNTIFS('Cư dân'!$B$2:$B$2000,A8,'Cư dân'!$O$2:$O$2000,"Đang ở") -> 6
A9: H008 | B9: 50 Lê Thanh Nghị | C9: =IFERROR(INDEX('Cư dân'!$C$2:$C$2000,MATCH(1,INDEX(('Cư dân'!$B$2:$B$2000=A9)*('Cư dân'!$I$2:$I$2000="Chủ hộ"),0),0)),"") -> Phạm Quế Anh | D9: =COUNTIFS('Cư dân'!$B$2:$B$2000,A9,'Cư dân'!$O$2:$O$2000,"Đang ở") -> 4
A10: H009 | B10: 52+54 Lê Thanh Nghị | C10: =IFERROR(INDEX('Cư dân'!$C$2:$C$2000,MATCH(1,INDEX(('Cư dân'!$B$2:$B$2000=A10)*('Cư dân'!$I$2:$I$2000="Chủ hộ"),0),0)),"") -> Lê Hồng Tịnh | D10: =COUNTIFS('Cư dân'!$B$2:$B$2000,A10,'Cư dân'!$O$2:$O$2000,"Đang ở") -> 5 | F10: Chủ hộ có ghi chú bán nhà/không ở – kiểm tra cả hộ
A11: H010 | B11: 56 Lê Thanh Nghị | C11: =IFERROR(INDEX('Cư dân'!$C$2:$C$2000,MATCH(1,INDEX(('Cư dân'!$B$2:$B$2000=A11)*('Cư dân'!$I$2:$I$2000="Chủ hộ"),0),0)),"") -> Phạm Quý Đức | D11: =COUNTIFS('Cư dân'!$B$2:$B$2000,A11,'Cư dân'!$O$2:$O$2000,"Đang ở") -> 2 | F11: Chủ hộ có ghi chú bán nhà/không ở – kiểm tra cả hộ
A12: H011 | B12: 56 Lê Thanh Nghị | C12: =IFERROR(INDEX('Cư dân'!$C$2:$C$2000,MATCH(1,INDEX(('Cư dân'!$B$2:$B$2000=A12)*('Cư dân'!$I$2:$I$2000="Chủ hộ"),0),0)),"") -> Phạm Quang Anh | D12: =COUNTIFS('Cư dân'!$B$2:$B$2000,A12,'Cư dân'!$O$2:$O$2000,"Đang ở") -> 3
A13: H012 | B13: 60 Lê Thanh Nghị | C13: =IFERROR(INDEX('Cư dân'!$C$2:$C$2000,MATCH(1,INDEX(('Cư dân'!$B$2:$B$2000=A13)*('Cư dân'!$I$2:$I$2000="Chủ hộ"),0),0)),"") -> Trần Thị Kim Mai | D13: =COUNTIFS('Cư dân'!$B$2:$B$2000,A13,'Cư dân'!$O$2:$O$2000,"Đang ở") -> 4
A14: H013 | B14: 62 Lê Thanh Nghị | C14: =IFERROR(INDEX('Cư dân'!$C$2:$C$2000,MATCH(1,INDEX(('Cư dân'!$B$2:$B$2000=A14)*('Cư dân'!$I$2:$I$2000="Chủ hộ"),0),0)),"") -> Nguyễn Quốc Thắng | D14: =COUNTIFS('Cư dân'!$B$2:$B$2000,A14,'Cư dân'!$O$2:$O$2000,"Đang ở") -> 4
A15: H014 | B15: 64 Lê Thanh Nghị | C15: =IFERROR(INDEX('Cư dân'!$C$2:$C$2000,MATCH(1,INDEX(('Cư dân'!$B$2:$B$2000=A15)*('Cư dân'!$I$2:$I$2000="Chủ hộ"),0),0)),"") -> Cao Trọng Ngọc | D15: =COUNTIFS('Cư dân'!$B$2:$B$2000,A15,'Cư dân'!$O$2:$O$2000,"Đang ở") -> 5
A16: H015 | B16: 66 Lê Thanh Nghị | C16: =IFERROR(INDEX('Cư dân'!$C$2:$C$2000,MATCH(1,INDEX(('Cư dân'!$B$2:$B$2000=A16)*('Cư dân'!$I$2:$I$2000="Chủ hộ"),0),0)),"") -> Ngô Văn Khiếu | D16: =COUNTIFS('Cư dân'!$B$2:$B$2000,A16,'Cư dân'!$O$2:$O$2000,"Đang ở") -> 4
A17: H016 | B17: 70 Lê Thanh Nghị | C17: =IFERROR(INDEX('Cư dân'!$C$2:$C$2000,MATCH(1,INDEX(('Cư dân'!$B$2:$B$2000=A17)*('Cư dân'!$I$2:$I$2000="Chủ hộ"),0),0)),"") -> Lê Minh Thông | D17: =COUNTIFS('Cư dân'!$B$2:$B$2000,A17,'Cư dân'!$O$2:$O$2000,"Đang ở") -> 3
A18: H017 | B18: 72 Lê Thanh Nghị | C18: =IFERROR(INDEX('Cư dân'!$C$2:$C$2000,MATCH(1,INDEX(('Cư dân'!$B$2:$B$2000=A18)*('Cư dân'!$I$2:$I$2000="Chủ hộ"),0),0)),"") -> Nguyễn Thị Mai Tần | D18: =COUNTIFS('Cư dân'!$B$2:$B$2000,A18,'Cư dân'!$O$2:$O$2000,"Đang ở") -> 1 | F18: Chủ hộ có ghi chú bán nhà/không ở – kiểm tra cả hộ
A19: H018 | B19: 72 Lê Thanh Nghị | C19: =IFERROR(INDEX('Cư dân'!$C$2:$C$2000,MATCH(1,INDEX(('Cư dân'!$B$2:$B$2000=A19)*('Cư dân'!$I$2:$I$2000="Chủ hộ"),0),0)),"") -> Trần Xuân Dương | D19: =COUNTIFS('Cư dân'!$B$2:$B$2000,A19,'Cư dân'!$O$2:$O$2000,"Đang ở") -> 4 | F19: Chủ hộ có ghi chú bán nhà/không ở – kiểm tra cả hộ
A20: H019 | B20: 72 Lê Thanh Nghị | C20: =IFERROR(INDEX('Cư dân'!$C$2:$C$2000,MATCH(1,INDEX(('Cư dân'!$B$2:$B$2000=A20)*('Cư dân'!$I$2:$I$2000="Chủ hộ"),0),0)),"") -> Trần Minh Dũng | D20: =COUNTIFS('Cư dân'!$B$2:$B$2000,A20,'Cư dân'!$O$2:$O$2000,"Đang ở") -> 4 | F20: Chủ hộ có ghi chú bán nhà/không ở – kiểm tra cả hộ
A21: H020 | B21: 74 Lê Thanh Nghị | C21: =IFERROR(INDEX('Cư dân'!$C$2:$C$2000,MATCH(1,INDEX(('Cư dân'!$B$2:$B$2000=A21)*('Cư dân'!$I$2:$I$2000="Chủ hộ"),0),0)),"") -> Đặng Huyền Thái | D21: =COUNTIFS('Cư dân'!$B$2:$B$2000,A21,'Cư dân'!$O$2:$O$2000,"Đang ở") -> 6 | F21: Chủ hộ có ghi chú bán nhà/không ở – kiểm tra cả hộ
A22: H021 | B22: 76 Lê Thanh Nghị | C22: =IFERROR(INDEX('Cư dân'!$C$2:$C$2000,MATCH(1,INDEX(('Cư dân'!$B$2:$B$2000=A22)*('Cư dân'!$I$2:$I$2000="Chủ hộ"),0),0)),"") -> Võ Trí Hải | D22: =COUNTIFS('Cư dân'!$B$2:$B$2000,A22,'Cư dân'!$O$2:$O$2000,"Đang ở") -> 4 | F22: Chủ hộ có ghi chú bán nhà/không ở – kiểm tra cả hộ
A23: H022 | B23: 78 Lê Thanh Nghị | C23: =IFERROR(INDEX('Cư dân'!$C$2:$C$2000,MATCH(1,INDEX(('Cư dân'!$B$2:$B$2000=A23)*('Cư dân'!$I$2:$I$2000="Chủ hộ"),0),0)),"") -> Đào Văn Đô | D23: =COUNTIFS('Cư dân'!$B$2:$B$2000,A23,'Cư dân'!$O$2:$O$2000,"Đang ở") -> 7
A24: H023 | B24: 84 Lê Thanh Nghị | C24: =IFERROR(INDEX('Cư dân'!$C$2:$C$2000,MATCH(1,INDEX(('Cư dân'!$B$2:$B$2000=A24)*('Cư dân'!$I$2:$I$2000="Chủ hộ"),0),0)),"") -> Hoàng Thị Tỉnh | D24: =COUNTIFS('Cư dân'!$B$2:$B$2000,A24,'Cư dân'!$O$2:$O$2000,"Đang ở") -> 1
A25: H024 | B25: 86 Lê Thanh Nghị | C25: =IFERROR(INDEX('Cư dân'!$C$2:$C$2000,MATCH(1,INDEX(('Cư dân'!$B$2:$B$2000=A25)*('Cư dân'!$I$2:$I$2000="Chủ hộ"),0),0)),"") -> Trần Vĩnh Diệu | D25: =COUNTIFS('Cư dân'!$B$2:$B$2000,A25,'Cư dân'!$O$2:$O$2000,"Đang ở") -> 4 | F25: Chủ hộ có ghi chú bán nhà/không ở – kiểm tra cả hộ
A26: H025 | B26: 88 Lê Thanh Nghị | C26: =IFERROR(INDEX('Cư dân'!$C$2:$C$2000,MATCH(1,INDEX(('Cư dân'!$B$2:$B$2000=A26)*('Cư dân'!$I$2:$I$2000="Chủ hộ"),0),0)),"") -> Lê Thị Phấn | D26: =COUNTIFS('Cư dân'!$B$2:$B$2000,A26,'Cư dân'!$O$2:$O$2000,"Đang ở") -> 6
A27: H026 | B27: 1 ngõ 78 Lê Thanh Nghị | C27: =IFERROR(INDEX('Cư dân'!$C$2:$C$2000,MATCH(1,INDEX(('Cư dân'!$B$2:$B$2000=A27)*('Cư dân'!$I$2:$I$2000="Chủ hộ"),0),0)),"") -> Nguyễn Việt Anh | D27: =COUNTIFS('Cư dân'!$B$2:$B$2000,A27,'Cư dân'!$O$2:$O$2000,"Đang ở") -> 4
A28: H027 | B28: 5 ngõ 78 Lê Thanh Nghị | C28: =IFERROR(INDEX('Cư dân'!$C$2:$C$2000,MATCH(1,INDEX(('Cư dân'!$B$2:$B$2000=A28)*('Cư dân'!$I$2:$I$2000="Chủ hộ"),0),0)),"") -> Phạm Ngọc Cảnh | D28: =COUNTIFS('Cư dân'!$B$2:$B$2000,A28,'Cư dân'!$O$2:$O$2000,"Đang ở") -> 4
A29: H028 | B29: 7 ngõ 78 Lê Thanh Nghị | C29: =IFERROR(INDEX('Cư dân'!$C$2:$C$2000,MATCH(1,INDEX(('Cư dân'!$B$2:$B$2000=A29)*('Cư dân'!$I$2:$I$2000="Chủ hộ"),0),0)),"") -> Trần Hà Liên | D29: =COUNTIFS('Cư dân'!$B$2:$B$2000,A29,'Cư dân'!$O$2:$O$2000,"Đang ở") -> 5
A30: H029 | B30: 9 ngõ 78 Lê Thanh Nghị | C30: =IFERROR(INDEX('Cư dân'!$C$2:$C$2000,MATCH(1,INDEX(('Cư dân'!$B$2:$B$2000=A30)*('Cư dân'!$I$2:$I$2000="Chủ hộ"),0),0)),"") -> Trần Văn Nhân | D30: =COUNTIFS('Cư dân'!$B$2:$B$2000,A30,'Cư dân'!$O$2:$O$2000,"Đang ở") -> 7 | F30: Chủ hộ có ghi chú bán nhà/không ở – kiểm tra cả hộ
A31: H030 | B31: 11 ngõ 78 Lê Thanh Nghị | C31: =IFERROR(INDEX('Cư dân'!$C$2:$C$2000,MATCH(1,INDEX(('Cư dân'!$B$2:$B$2000=A31)*('Cư dân'!$I$2:$I$2000="Chủ hộ"),0),0)),"") -> Trịnh Thị Minh Hằng | D31: =COUNTIFS('Cư dân'!$B$2:$B$2000,A31,'Cư dân'!$O$2:$O$2000,"Đang ở") -> 2
A32: H031 | B32: 13 ngõ 78 Lê Thanh Nghị | C32: =IFERROR(INDEX('Cư dân'!$C$2:$C$2000,MATCH(1,INDEX(('Cư dân'!$B$2:$B$2000=A32)*('Cư dân'!$I$2:$I$2000="Chủ hộ"),0),0)),"") -> Nguyễn Thị Minh Hòa | D32: =COUNTIFS('Cư dân'!$B$2:$B$2000,A32,'Cư dân'!$O$2:$O$2000,"Đang ở") -> 2
A33: H032 | B33: 15 ngõ 78 Lê Thanh Nghị | C33: =IFERROR(INDEX('Cư dân'!$C$2:$C$2000,MATCH(1,INDEX(('Cư dân'!$B$2:$B$2000=A33)*('Cư dân'!$I$2:$I$2000="Chủ hộ"),0),0)),"") -> Trần Thị Lan | D33: =COUNTIFS('Cư dân'!$B$2:$B$2000,A33,'Cư dân'!$O$2:$O$2000,"Đang ở") -> 6
A34: H033 | B34: 15 ngõ 78 Lê Thanh Nghị | C34: =IFERROR(INDEX('Cư dân'!$C$2:$C$2000,MATCH(1,INDEX(('Cư dân'!$B$2:$B$2000=A34)*('Cư dân'!$I$2:$I$2000="Chủ hộ"),0),0)),"") -> Nguyễn Thị Uyển | D34: =COUNTIFS('Cư dân'!$B$2:$B$2000,A34,'Cư dân'!$O$2:$O$2000,"Đang ở") -> 1 | F34: Chủ hộ có ghi chú bán nhà/không ở – kiểm tra cả hộ
A35: H034 | B35: 17 ngõ 78 Lê Thanh Nghị | C35: =IFERROR(INDEX('Cư dân'!$C$2:$C$2000,MATCH(1,INDEX(('Cư dân'!$B$2:$B$2000=A35)*('Cư dân'!$I$2:$I$2000="Chủ hộ"),0),0)),"") -> Lê Thị Hải Anh | D35: =COUNTIFS('Cư dân'!$B$2:$B$2000,A35,'Cư dân'!$O$2:$O$2000,"Đang ở") -> 6
A36: H035 | B36: 19 ngõ 78 Lê Thanh Nghị | C36: =IFERROR(INDEX('Cư dân'!$C$2:$C$2000,MATCH(1,INDEX(('Cư dân'!$B$2:$B$2000=A36)*('Cư dân'!$I$2:$I$2000="Chủ hộ"),0),0)),"") -> Đỗ Năng Anh | D36: =COUNTIFS('Cư dân'!$B$2:$B$2000,A36,'Cư dân'!$O$2:$O$2000,"Đang ở") -> 4
A37: H036 | B37: 21 ngõ 78 Lê Thanh Nghị | C37: =IFERROR(INDEX('Cư dân'!$C$2:$C$2000,MATCH(1,INDEX(('Cư dân'!$B$2:$B$2000=A37)*('Cư dân'!$I$2:$I$2000="Chủ hộ"),0),0)),"") -> Thái Thị Chiến | D37: =COUNTIFS('Cư dân'!$B$2:$B$2000,A37,'Cư dân'!$O$2:$O$2000,"Đang ở") -> 5
A38: H037 | B38: 21 ngõ 78 Lê Thanh Nghị | C38: =IFERROR(INDEX('Cư dân'!$C$2:$C$2000,MATCH(1,INDEX(('Cư dân'!$B$2:$B$2000=A38)*('Cư dân'!$I$2:$I$2000="Chủ hộ"),0),0)),"") -> Vũ Minh Tuệ | D38: =COUNTIFS('Cư dân'!$B$2:$B$2000,A38,'Cư dân'!$O$2:$O$2000,"Đang ở") -> 4
A39: H038 | B39: 3 ngõ 17 Lê Thanh Nghị | C39: =IFERROR(INDEX('Cư dân'!$C$2:$C$2000,MATCH(1,INDEX(('Cư dân'!$B$2:$B$2000=A39)*('Cư dân'!$I$2:$I$2000="Chủ hộ"),0),0)),"") -> Nguyễn Phương Thùy | D39: =COUNTIFS('Cư dân'!$B$2:$B$2000,A39,'Cư dân'!$O$2:$O$2000,"Đang ở") -> 4
A40: H039 | B40: 4 ngõ 17 Tạ Quang Bửu | C40: =IFERROR(INDEX('Cư dân'!$C$2:$C$2000,MATCH(1,INDEX(('Cư dân'!$B$2:$B$2000=A40)*('Cư dân'!$I$2:$I$2000="Chủ hộ"),0),0)),"") -> Bùi Ngọc Quang | D40: =COUNTIFS('Cư dân'!$B$2:$B$2000,A40,'Cư dân'!$O$2:$O$2000,"Đang ở") -> 3
...

Sheet Cư dân
A1: Mã CD | B1: Mã hộ | C1: Họ và tên | D1: Giới tính | E1: Ngày sinh | F1: Năm sinh | G1: Tuổi | H1: Nhóm tuổi | I1: Quan hệ với chủ hộ | J1: Địa chỉ | K1: CCCD | L1: Điện thoại | M1: Nghề nghiệp | N1: Cử tri | O1: Tình trạng | P1: Ghi chú | Q1: Nguồn thông tin | R1: Cần kiểm tra
A2: CD0001 | B2: H001 | C2: Phạm Thị Ngân | D2: Nữ | E2: 13150 | F2: 1936 | G2: =IF(F2="","",YEAR(TODAY())-F2) -> 90 | H2: =IF(C2="","",IF(G2="","Thiếu thông tin",IF(G2<6,"Trẻ em",IF(G2<23,"Học sinh / Sinh viên",IF(G2<60,"Đang đi làm","Nghỉ hưu"))))) -> Nghỉ hưu | I2: Chủ hộ | J2: =IF(B2="","",IFERROR(INDEX('Hộ gia đình'!$B$2:$B$2000,MATCH(B2,'Hộ gia đình'!$A$2:$A$2000,0)),"Mã hộ không tồn tại")) -> 40 Lê Thanh Nghị | K2: 001136007902 | M2: Hưu trí | N2: Có | O2: Đang ở | P2: Ở quê | Q2: Sổ cư dân, DS cử tri | R2: Ghi chú cho thấy có thể không còn ở tổ – kiểm tra Tình trạng
A3: CD0002 | B3: H001 | C3: Tạ Văn Long | F3: 1961 | G3: =IF(F3="","",YEAR(TODAY())-F3) -> 65 | H3: =IF(C3="","",IF(G3="","Thiếu thông tin",IF(G3<6,"Trẻ em",IF(G3<23,"Học sinh / Sinh viên",IF(G3<60,"Đang đi làm","Nghỉ hưu"))))) -> Nghỉ hưu | J3: =IF(B3="","",IFERROR(INDEX('Hộ gia đình'!$B$2:$B$2000,MATCH(B3,'Hộ gia đình'!$A$2:$A$2000,0)),"Mã hộ không tồn tại")) -> 40 Lê Thanh Nghị | N3: Không | O3: Đang ở | Q3: Sổ cư dân
A4: CD0003 | B4: H001 | C4: Trần Mai Anh | F4: 1966 | G4: =IF(F4="","",YEAR(TODAY())-F4) -> 60 | H4: =IF(C4="","",IF(G4="","Thiếu thông tin",IF(G4<6,"Trẻ em",IF(G4<23,"Học sinh / Sinh viên",IF(G4<60,"Đang đi làm","Nghỉ hưu"))))) -> Nghỉ hưu | J4: =IF(B4="","",IFERROR(INDEX('Hộ gia đình'!$B$2:$B$2000,MATCH(B4,'Hộ gia đình'!$A$2:$A$2000,0)),"Mã hộ không tồn tại")) -> 40 Lê Thanh Nghị | N4: Không | O4: Đang ở | Q4: Sổ cư dân
A5: CD0004 | B5: H001 | C5: Tạ Anh Quân | E5: 33828 | F5: 1992 | G5: =IF(F5="","",YEAR(TODAY())-F5) -> 34 | H5: =IF(C5="","",IF(G5="","Thiếu thông tin",IF(G5<6,"Trẻ em",IF(G5<23,"Học sinh / Sinh viên",IF(G5<60,"Đang đi làm","Nghỉ hưu"))))) -> Đang đi làm | J5: =IF(B5="","",IFERROR(INDEX('Hộ gia đình'!$B$2:$B$2000,MATCH(B5,'Hộ gia đình'!$A$2:$A$2000,0)),"Mã hộ không tồn tại")) -> 40 Lê Thanh Nghị | N5: Không | O5: Đang ở | Q5: Sổ cư dân
A6: CD0005 | B6: H001 | C6: Tạ Đình Đức | E6: 36746 | F6: 2000 | G6: =IF(F6="","",YEAR(TODAY())-F6) -> 26 | H6: =IF(C6="","",IF(G6="","Thiếu thông tin",IF(G6<6,"Trẻ em",IF(G6<23,"Học sinh / Sinh viên",IF(G6<60,"Đang đi làm","Nghỉ hưu"))))) -> Đang đi làm | J6: =IF(B6="","",IFERROR(INDEX('Hộ gia đình'!$B$2:$B$2000,MATCH(B6,'Hộ gia đình'!$A$2:$A$2000,0)),"Mã hộ không tồn tại")) -> 40 Lê Thanh Nghị | N6: Không | O6: Đang ở | Q6: Sổ cư dân, Quân sự 2005
A7: CD0006 | B7: H001 | C7: Tạ Đình Quang Hưng | F7: 2020 | G7: =IF(F7="","",YEAR(TODAY())-F7) -> 6 | H7: =IF(C7="","",IF(G7="","Thiếu thông tin",IF(G7<6,"Trẻ em",IF(G7<23,"Học sinh / Sinh viên",IF(G7<60,"Đang đi làm","Nghỉ hưu"))))) -> Học sinh / Sinh viên | J7: =IF(B7="","",IFERROR(INDEX('Hộ gia đình'!$B$2:$B$2000,MATCH(B7,'Hộ gia đình'!$A$2:$A$2000,0)),"Mã hộ không tồn tại")) -> 40 Lê Thanh Nghị | N7: Không | O7: Đang ở | Q7: Sổ cư dân, Quân sự 2005
A8: CD0007 | B8: H001 | C8: Nguyễn Tiến Tiến | D8: Nam | E8: 22088 | F8: 1960 | G8: =IF(F8="","",YEAR(TODAY())-F8) -> 66 | H8: =IF(C8="","",IF(G8="","Thiếu thông tin",IF(G8<6,"Trẻ em",IF(G8<23,"Học sinh / Sinh viên",IF(G8<60,"Đang đi làm","Nghỉ hưu"))))) -> Nghỉ hưu | J8: =IF(B8="","",IFERROR(INDEX('Hộ gia đình'!$B$2:$B$2000,MATCH(B8,'Hộ gia đình'!$A$2:$A$2000,0)),"Mã hộ không tồn tại")) -> 40 Lê Thanh Nghị | K8: 001060008221 | M8: Hưu trí | N8: Có | O8: Đang ở | Q8: DS cử tri
A9: CD0008 | B9: H001 | C9: Tạ Thi Lan | D9: Nữ | E9: 24666 | F9: 1967 | G9: =IF(F9="","",YEAR(TODAY())-F9) -> 59 | H9: =IF(C9="","",IF(G9="","Thiếu thông tin",IF(G9<6,"Trẻ em",IF(G9<23,"Học sinh / Sinh viên",IF(G9<60,"Đang đi làm","Nghỉ hưu"))))) -> Đang đi làm | J9: =IF(B9="","",IFERROR(INDEX('Hộ gia đình'!$B$2:$B$2000,MATCH(B9,'Hộ gia đình'!$A$2:$A$2000,0)),"Mã hộ không tồn tại")) -> 40 Lê Thanh Nghị | K9: 011677014757 | M9: CN | N9: Có | O9: Đang ở | Q9: DS cử tri
A10: CD0009 | B10: H001 | C10: Nguyễn Thị Thảo My | D10: Nữ | E10: 35397 | F10: 1996 | G10: =IF(F10="","",YEAR(TODAY())-F10) -> 30 | H10: =IF(C10="","",IF(G10="","Thiếu thông tin",IF(G10<6,"Trẻ em",IF(G10<23,"Học sinh / Sinh viên",IF(G10<60,"Đang đi làm","Nghỉ hưu"))))) -> Đang đi làm | J10: =IF(B10="","",IFERROR(INDEX('Hộ gia đình'!$B$2:$B$2000,MATCH(B10,'Hộ gia đình'!$A$2:$A$2000,0)),"Mã hộ không tồn tại")) -> 40 Lê Thanh Nghị | K10: 001196013999 | M10: nhân viên | N10: Có | O10: Đang ở | Q10: DS cử tri
A11: CD0010 | B11: H001 | C11: Nguyễn Khoa Đăng | D11: Nam | E11: 38111 | F11: 2004 | G11: =IF(F11="","",YEAR(TODAY())-F11) -> 22 | H11: =IF(C11="","",IF(G11="","Thiếu thông tin",IF(G11<6,"Trẻ em",IF(G11<23,"Học sinh / Sinh viên",IF(G11<60,"Đang đi làm","Nghỉ hưu"))))) -> Học sinh / Sinh viên | J11: =IF(B11="","",IFERROR(INDEX('Hộ gia đình'!$B$2:$B$2000,MATCH(B11,'Hộ gia đình'!$A$2:$A$2000,0)),"Mã hộ không tồn tại")) -> 40 Lê Thanh Nghị | K11: 001204031774 | M11: sinh viên | N11: Có | O11: Đang ở | Q11: DS cử tri
A12: CD0011 | B12: H002 | C12: Tạ Đình Tuấn | F12: 1972 | G12: =IF(F12="","",YEAR(TODAY())-F12) -> 54 | H12: =IF(C12="","",IF(G12="","Thiếu thông tin",IF(G12<6,"Trẻ em",IF(G12<23,"Học sinh / Sinh viên",IF(G12<60,"Đang đi làm","Nghỉ hưu"))))) -> Đang đi làm | I12: Chủ hộ | J12: =IF(B12="","",IFERROR(INDEX('Hộ gia đình'!$B$2:$B$2000,MATCH(B12,'Hộ gia đình'!$A$2:$A$2000,0)),"Mã hộ không tồn tại")) -> 42 Lê Thanh Nghị | N12: Không | O12: Đang ở | Q12: Sổ cư dân
A13: CD0012 | B13: H002 | C13: Doãn Ngọc Diệp | F13: 1973 | G13: =IF(F13="","",YEAR(TODAY())-F13) -> 53 | H13: =IF(C13="","",IF(G13="","Thiếu thông tin",IF(G13<6,"Trẻ em",IF(G13<23,"Học sinh / Sinh viên",IF(G13<60,"Đang đi làm","Nghỉ hưu"))))) -> Đang đi làm | J13: =IF(B13="","",IFERROR(INDEX('Hộ gia đình'!$B$2:$B$2000,MATCH(B13,'Hộ gia đình'!$A$2:$A$2000,0)),"Mã hộ không tồn tại")) -> 42 Lê Thanh Nghị | N13: Không | O13: Đang ở | Q13: Sổ cư dân
A14: CD0013 | B14: H002 | C14: Tạ Tuấn Việt | F14: 1998 | G14: =IF(F14="","",YEAR(TODAY())-F14) -> 28 | H14: =IF(C14="","",IF(G14="","Thiếu thông tin",IF(G14<6,"Trẻ em",IF(G14<23,"Học sinh / Sinh viên",IF(G14<60,"Đang đi làm","Nghỉ hưu"))))) -> Đang đi làm | J14: =IF(B14="","",IFERROR(INDEX('Hộ gia đình'!$B$2:$B$2000,MATCH(B14,'Hộ gia đình'!$A$2:$A$2000,0)),"Mã hộ không tồn tại")) -> 42 Lê Thanh Nghị | N14: Không | O14: Đang ở | Q14: Sổ cư dân, Quân sự 2005
A15: CD0014 | B15: H002 | C15: Tạ Tuấn Phương | E15: 36690 | F15: 2000 | G15: =IF(F15="","",YEAR(TODAY())-F15) -> 26 | H15: =IF(C15="","",IF(G15="","Thiếu thông tin",IF(G15<6,"Trẻ em",IF(G15<23,"Học sinh / Sinh viên",IF(G15<60,"Đang đi làm","Nghỉ hưu"))))) -> Đang đi làm | J15: =IF(B15="","",IFERROR(INDEX('Hộ gia đình'!$B$2:$B$2000,MATCH(B15,'Hộ gia đình'!$A$2:$A$2000,0)),"Mã hộ không tồn tại")) -> 42 Lê Thanh Nghị | N15: Không | O15: Đang ở | Q15: Sổ cư dân, Quân sự 2005
A16: CD0015 | B16: H002 | C16: Tạ Đình Tuấn Khôi | E16: 39912 | F16: 2009 | G16: =IF(F16="","",YEAR(TODAY())-F16) -> 17 | H16: =IF(C16="","",IF(G16="","Thiếu thông tin",IF(G16<6,"Trẻ em",IF(G16<23,"Học sinh / Sinh viên",IF(G16<60,"Đang đi làm","Nghỉ hưu"))))) -> Học sinh / Sinh viên | J16: =IF(B16="","",IFERROR(INDEX('Hộ gia đình'!$B$2:$B$2000,MATCH(B16,'Hộ gia đình'!$A$2:$A$2000,0)),"Mã hộ không tồn tại")) -> 42 Lê Thanh Nghị | N16: Không | O16: Đang ở | Q16: Sổ cư dân, Quân sự 2005
A17: CD0016 | B17: H003 | C17: Lê Thị Hồng | D17: Nữ | E17: 16682 | F17: 1945 | G17: =IF(F17="","",YEAR(TODAY())-F17) -> 81 | H17: =IF(C17="","",IF(G17="","Thiếu thông tin",IF(G17<6,"Trẻ em",IF(G17<23,"Học sinh / Sinh viên",IF(G17<60,"Đang đi làm","Nghỉ hưu"))))) -> Nghỉ hưu | I17: Chủ hộ | J17: =IF(B17="","",IFERROR(INDEX('Hộ gia đình'!$B$2:$B$2000,MATCH(B17,'Hộ gia đình'!$A$2:$A$2000,0)),"Mã hộ không tồn tại")) -> 44 Lê Thanh Nghị | K17: 001145006244 | M17: Hưu trí | N17: Có | O17: Đang ở | Q17: Sổ cư dân, DS cử tri
A18: CD0017 | B18: H004 | C18: Nguyễn Thị Bích Huệ | F18: 1975 | G18: =IF(F18="","",YEAR(TODAY())-F18) -> 51 | H18: =IF(C18="","",IF(G18="","Thiếu thông tin",IF(G18<6,"Trẻ em",IF(G18<23,"Học sinh / Sinh viên",IF(G18<60,"Đang đi làm","Nghỉ hưu"))))) -> Đang đi làm | I18: Chủ hộ | J18: =IF(B18="","",IFERROR(INDEX('Hộ gia đình'!$B$2:$B$2000,MATCH(B18,'Hộ gia đình'!$A$2:$A$2000,0)),"Mã hộ không tồn tại")) -> 44 Lê Thanh Nghị | N18: Không | O18: Đang ở | Q18: Sổ cư dân
A19: CD0018 | B19: H005 | C19: Nguyễn Thị Thu Hằng | D19: Nữ | E19: 28299 | F19: 1977 | G19: =IF(F19="","",YEAR(TODAY())-F19) -> 49 | H19: =IF(C19="","",IF(G19="","Thiếu thông tin",IF(G19<6,"Trẻ em",IF(G19<23,"Học sinh / Sinh viên",IF(G19<60,"Đang đi làm","Nghỉ hưu"))))) -> Đang đi làm | I19: Chủ hộ | J19: =IF(B19="","",IFERROR(INDEX('Hộ gia đình'!$B$2:$B$2000,MATCH(B19,'Hộ gia đình'!$A$2:$A$2000,0)),"Mã hộ không tồn tại")) -> 44 Lê Thanh Nghị | K19: 001177003308 | M19: Kế toán | N19: Có | O19: Đang ở | Q19: Sổ cư dân, DS cử tri
A20: CD0019 | B20: H005 | C20: Nguyễn Công Giảng | F20: 1973 | G20: =IF(F20="","",YEAR(TODAY())-F20) -> 53 | H20: =IF(C20="","",IF(G20="","Thiếu thông tin",IF(G20<6,"Trẻ em",IF(G20<23,"Học sinh / Sinh viên",IF(G20<60,"Đang đi làm","Nghỉ hưu"))))) -> Đang đi làm | J20: =IF(B20="","",IFERROR(INDEX('Hộ gia đình'!$B$2:$B$2000,MATCH(B20,'Hộ gia đình'!$A$2:$A$2000,0)),"Mã hộ không tồn tại")) -> 44 Lê Thanh Nghị | N20: Không | O20: Đang ở | Q20: Sổ cư dân
A21: CD0020 | B21: H005 | C21: Nguyễn Minh Ngân | E21: 41419 | F21: 2013 | G21: =IF(F21="","",YEAR(TODAY())-F21) -> 13 | H21: =IF(C21="","",IF(G21="","Thiếu thông tin",IF(G21<6,"Trẻ em",IF(G21<23,"Học sinh / Sinh viên",IF(G21<60,"Đang đi làm","Nghỉ hưu"))))) -> Học sinh / Sinh viên | J21: =IF(B21="","",IFERROR(INDEX('Hộ gia đình'!$B$2:$B$2000,MATCH(B21,'Hộ gia đình'!$A$2:$A$2000,0)),"Mã hộ không tồn tại")) -> 44 Lê Thanh Nghị | N21: Không | O21: Đang ở | Q21: Sổ cư dân, Quân sự 2005
A22: CD0021 | B22: H005 | C22: Nguyễn Công Giang | E22: 40738 | F22: 2011 | G22: =IF(F22="","",YEAR(TODAY())-F22) -> 15 | H22: =IF(C22="","",IF(G22="","Thiếu thông tin",IF(G22<6,"Trẻ em",IF(G22<23,"Học sinh / Sinh viên",IF(G22<60,"Đang đi làm","Nghỉ hưu"))))) -> Học sinh / Sinh viên | J22: =IF(B22="","",IFERROR(INDEX('Hộ gia đình'!$B$2:$B$2000,MATCH(B22,'Hộ gia đình'!$A$2:$A$2000,0)),"Mã hộ không tồn tại")) -> 44 Lê Thanh Nghị | N22: Không | O22: Đang ở | Q22: Sổ cư dân, Quân sự 2005
A23: CD0022 | B23: H006 | C23: Phạm Văn Khôi | D23: Nam | F23: 1934 | G23: =IF(F23="","",YEAR(TODAY())-F23) -> 92 | H23: =IF(C23="","",IF(G23="","Thiếu thông tin",IF(G23<6,"Trẻ em",IF(G23<23,"Học sinh / Sinh viên",IF(G23<60,"Đang đi làm","Nghỉ hưu"))))) -> Nghỉ hưu | I23: Chủ hộ | J23: =IF(B23="","",IFERROR(INDEX('Hộ gia đình'!$B$2:$B$2000,MATCH(B23,'Hộ gia đình'!$A$2:$A$2000,0)),"Mã hộ không tồn tại")) -> 46 Lê Thanh Nghị | K23: 001034000857 | M23: hưu trí | N23: Có | O23: Đang ở | Q23: Sổ cư dân, DS cử tri | R23: DS cử tri ghi ngày sinh 13/05/1943
A24: CD0023 | B24: H006 | C24: Đỗ Thị Hạnh | D24: Nữ | E24: 15797 | F24: 1943 | G24: =IF(F24="","",YEAR(TODAY())-F24) -> 83 | H24: =IF(C24="","",IF(G24="","Thiếu thông tin",IF(G24<6,"Trẻ em",IF(G24<23,"Học sinh / Sinh viên",IF(G24<60,"Đang đi làm","Nghỉ hưu"))))) -> Nghỉ hưu | J24: =IF(B24="","",IFERROR(INDEX('Hộ gia đình'!$B$2:$B$2000,MATCH(B24,'Hộ gia đình'!$A$2:$A$2000,0)),"Mã hộ không tồn tại")) -> 46 Lê Thanh Nghị | K24: 001143004697 | M24: hưu trí | N24: Có | O24: Đang ở | Q24: Sổ cư dân, DS cử tri
A25: CD0024 | B25: H006 | C25: Phạm Mai Khánh | D25: Nam | E25: 27323 | F25: 1974 | G25: =IF(F25="","",YEAR(TODAY())-F25) -> 52 | H25: =IF(C25="","",IF(G25="","Thiếu thông tin",IF(G25<6,"Trẻ em",IF(G25<23,"Học sinh / Sinh viên",IF(G25<60,"Đang đi làm","Nghỉ hưu"))))) -> Đang đi làm | J25: =IF(B25="","",IFERROR(INDEX('Hộ gia đình'!$B$2:$B$2000,MATCH(B25,'Hộ gia đình'!$A$2:$A$2000,0)),"Mã hộ không tồn tại")) -> 46 Lê Thanh Nghị | K25: 001074003138 | M25: cán bộ | N25: Có | O25: Đang ở | Q25: Sổ cư dân, DS cử tri
A26: CD0025 | B26: H006 | C26: Vũ Thị Giêng | D26: Nữ | E26: 31846 | F26: 1987 | G26: =IF(F26="","",YEAR(TODAY())-F26) -> 39 | H26: =IF(C26="","",IF(G26="","Thiếu thông tin",IF(G26<6,"Trẻ em",IF(G26<23,"Học sinh / Sinh viên",IF(G26<60,"Đang đi làm","Nghỉ hưu"))))) -> Đang đi làm | J26: =IF(B26="","",IFERROR(INDEX('Hộ gia đình'!$B$2:$B$2000,MATCH(B26,'Hộ gia đình'!$A$2:$A$2000,0)),"Mã hộ không tồn tại")) -> 46 Lê Thanh Nghị | K26: 033187000118 | M26: cán bộ | N26: Có | O26: Đang ở | Q26: Sổ cư dân, DS cử tri
A27: CD0026 | B27: H006 | C27: Phạm Tuyết Mai | D27: Nữ | E27: 23525 | F27: 1964 | G27: =IF(F27="","",YEAR(TODAY())-F27) -> 62 | H27: =IF(C27="","",IF(G27="","Thiếu thông tin",IF(G27<6,"Trẻ em",IF(G27<23,"Học sinh / Sinh viên",IF(G27<60,"Đang đi làm","Nghỉ hưu"))))) -> Nghỉ hưu | J27: =IF(B27="","",IFERROR(INDEX('Hộ gia đình'!$B$2:$B$2000,MATCH(B27,'Hộ gia đình'!$A$2:$A$2000,0)),"Mã hộ không tồn tại")) -> 46 Lê Thanh Nghị | K27: 001164022483 | M27: cán bộ | N27: Có | O27: Đang ở | Q27: Sổ cư dân, DS cử tri
A28: CD0027 | B28: H006 | C28: Phạm Lê Đức | F28: 1993 | G28: =IF(F28="","",YEAR(TODAY())-F28) -> 33 | H28: =IF(C28="","",IF(G28="","Thiếu thông tin",IF(G28<6,"Trẻ em",IF(G28<23,"Học sinh / Sinh viên",IF(G28<60,"Đang đi làm","Nghỉ hưu"))))) -> Đang đi làm | J28: =IF(B28="","",IFERROR(INDEX('Hộ gia đình'!$B$2:$B$2000,MATCH(B28,'Hộ gia đình'!$A$2:$A$2000,0)),"Mã hộ không tồn tại")) -> 46 Lê Thanh Nghị | N28: Không | O28: Đang ở | Q28: Sổ cư dân
A29: CD0028 | B29: H006 | C29: Phạm Vũ Khôi Nguyên | E29: 43324 | F29: 2018 | G29: =IF(F29="","",YEAR(TODAY())-F29) -> 8 | H29: =IF(C29="","",IF(G29="","Thiếu thông tin",IF(G29<6,"Trẻ em",IF(G29<23,"Học sinh / Sinh viên",IF(G29<60,"Đang đi làm","Nghỉ hưu"))))) -> Học sinh / Sinh viên | J29: =IF(B29="","",IFERROR(INDEX('Hộ gia đình'!$B$2:$B$2000,MATCH(B29,'Hộ gia đình'!$A$2:$A$2000,0)),"Mã hộ không tồn tại")) -> 46 Lê Thanh Nghị | N29: Không | O29: Đang ở | Q29: Sổ cư dân, Quân sự 2005
A30: CD0029 | B30: H006 | C30: Phạm Vũ Khánh Hà | E30: 41933 | F30: 2014 | G30: =IF(F30="","",YEAR(TODAY())-F30) -> 12 | H30: =IF(C30="","",IF(G30="","Thiếu thông tin",IF(G30<6,"Trẻ em",IF(G30<23,"Học sinh / Sinh viên",IF(G30<60,"Đang đi làm","Nghỉ hưu"))))) -> Học sinh / Sinh viên | J30: =IF(B30="","",IFERROR(INDEX('Hộ gia đình'!$B$2:$B$2000,MATCH(B30,'Hộ gia đình'!$A$2:$A$2000,0)),"Mã hộ không tồn tại")) -> 46 Lê Thanh Nghị | N30: Không | O30: Đang ở | Q30: Sổ cư dân, Quân sự 2005
A31: CD0030 | B31: H007 | C31: Quách Thị Hương | D31: Nữ | E31: 19850 | F31: 1954 | G31: =IF(F31="","",YEAR(TODAY())-F31) -> 72 | H31: =IF(C31="","",IF(G31="","Thiếu thông tin",IF(G31<6,"Trẻ em",IF(G31<23,"Học sinh / Sinh viên",IF(G31<60,"Đang đi làm","Nghỉ hưu"))))) -> Nghỉ hưu | I31: Chủ hộ | J31: =IF(B31="","",IFERROR(INDEX('Hộ gia đình'!$B$2:$B$2000,MATCH(B31,'Hộ gia đình'!$A$2:$A$2000,0)),"Mã hộ không tồn tại")) -> 48 Lê Thanh Nghị | K31: 026154001748 | M31: Hưu trí | N31: Có | O31: Đang ở | Q31: Sổ cư dân, DS cử tri
A32: CD0031 | B32: H007 | C32: Đoàn Minh Mẫn | D32: Nam | E32: 14376 | F32: 1939 | G32: =IF(F32="","",YEAR(TODAY())-F32) -> 87 | H32: =IF(C32="","",IF(G32="","Thiếu thông tin",IF(G32<6,"Trẻ em",IF(G32<23,"Học sinh / Sinh viên",IF(G32<60,"Đang đi làm","Nghỉ hưu"))))) -> Nghỉ hưu | J32: =IF(B32="","",IFERROR(INDEX('Hộ gia đình'!$B$2:$B$2000,MATCH(B32,'Hộ gia đình'!$A$2:$A$2000,0)),"Mã hộ không tồn tại")) -> 48 Lê Thanh Nghị | K32: 001039002876 | M32: Hưu trí | N32: Có | O32: Đang ở | Q32: Sổ cư dân, DS cử tri
A33: CD0032 | B33: H007 | C33: Đoàn Duy Thành | F33: 1981 | G33: =IF(F33="","",YEAR(TODAY())-F33) -> 45 | H33: =IF(C33="","",IF(G33="","Thiếu thông tin",IF(G33<6,"Trẻ em",IF(G33<23,"Học sinh / Sinh viên",IF(G33<60,"Đang đi làm","Nghỉ hưu"))))) -> Đang đi làm | J33: =IF(B33="","",IFERROR(INDEX('Hộ gia đình'!$B$2:$B$2000,MATCH(B33,'Hộ gia đình'!$A$2:$A$2000,0)),"Mã hộ không tồn tại")) -> 48 Lê Thanh Nghị | N33: Không | O33: Đang ở | Q33: Sổ cư dân
A34: CD0033 | B34: H007 | C34: Nguyễn Thanh Vân | F34: 1982 | G34: =IF(F34="","",YEAR(TODAY())-F34) -> 44 | H34: =IF(C34="","",IF(G34="","Thiếu thông tin",IF(G34<6,"Trẻ em",IF(G34<23,"Học sinh / Sinh viên",IF(G34<60,"Đang đi làm","Nghỉ hưu"))))) -> Đang đi làm | J34: =IF(B34="","",IFERROR(INDEX('Hộ gia đình'!$B$2:$B$2000,MATCH(B34,'Hộ gia đình'!$A$2:$A$2000,0)),"Mã hộ không tồn tại")) -> 48 Lê Thanh Nghị | N34: Không | O34: Đang ở | Q34: Sổ cư dân
A35: CD0034 | B35: H007 | C35: Đoàn Duy Tùng | D35: Nam | E35: 32559 | F35: 1989 | G35: =IF(F35="","",YEAR(TODAY())-F35) -> 37 | H35: =IF(C35="","",IF(G35="","Thiếu thông tin",IF(G35<6,"Trẻ em",IF(G35<23,"Học sinh / Sinh viên",IF(G35<60,"Đang đi làm","Nghỉ hưu"))))) -> Đang đi làm | J35: =IF(B35="","",IFERROR(INDEX('Hộ gia đình'!$B$2:$B$2000,MATCH(B35,'Hộ gia đình'!$A$2:$A$2000,0)),"Mã hộ không tồn tại")) -> 48 Lê Thanh Nghị | K35: 031089012896 | M35: cán bộ | N35: Có | O35: Đang ở | Q35: Sổ cư dân, DS cử tri
A36: CD0035 | B36: H007 | C36: Đoàn Nguyễn Gia Vinh | F36: 2010 | G36: =IF(F36="","",YEAR(TODAY())-F36) -> 16 | H36: =IF(C36="","",IF(G36="","Thiếu thông tin",IF(G36<6,"Trẻ em",IF(G36<23,"Học sinh / Sinh viên",IF(G36<60,"Đang đi làm","Nghỉ hưu"))))) -> Học sinh / Sinh viên | J36: =IF(B36="","",IFERROR(INDEX('Hộ gia đình'!$B$2:$B$2000,MATCH(B36,'Hộ gia đình'!$A$2:$A$2000,0)),"Mã hộ không tồn tại")) -> 48 Lê Thanh Nghị | N36: Không | O36: Đang ở | Q36: Sổ cư dân, Quân sự 2005
A37: CD0036 | B37: H008 | C37: Phạm Quế Anh | D37: Nữ | E37: 22907 | F37: 1962 | G37: =IF(F37="","",YEAR(TODAY())-F37) -> 64 | H37: =IF(C37="","",IF(G37="","Thiếu thông tin",IF(G37<6,"Trẻ em",IF(G37<23,"Học sinh / Sinh viên",IF(G37<60,"Đang đi làm","Nghỉ hưu"))))) -> Nghỉ hưu | I37: Chủ hộ | J37: =IF(B37="","",IFERROR(INDEX('Hộ gia đình'!$B$2:$B$2000,MATCH(B37,'Hộ gia đình'!$A$2:$A$2000,0)),"Mã hộ không tồn tại")) -> 50 Lê Thanh Nghị | K37: 001162019842 | M37: hưu trí | N37: Có | O37: Đang ở | Q37: Sổ cư dân, DS cử tri
A38: CD0037 | B38: H008 | C38: Trần Văn Lượng | D38: Nam | E38: 22169 | F38: 1960 | G38: =IF(F38="","",YEAR(TODAY())-F38) -> 66 | H38: =IF(C38="","",IF(G38="","Thiếu thông tin",IF(G38<6,"Trẻ em",IF(G38<23,"Học sinh / Sinh viên",IF(G38<60,"Đang đi làm","Nghỉ hưu"))))) -> Nghỉ hưu | J38: =IF(B38="","",IFERROR(INDEX('Hộ gia đình'!$B$2:$B$2000,MATCH(B38,'Hộ gia đình'!$A$2:$A$2000,0)),"Mã hộ không tồn tại")) -> 50 Lê Thanh Nghị | K38: 034060008609 | M38: hưu trí | N38: Có | O38: Đang ở | Q38: Sổ cư dân, DS cử tri
A39: CD0038 | B39: H008 | C39: Trấn Quang Anh | E39: 31663 | F39: 1986 | G39: =IF(F39="","",YEAR(TODAY())-F39) -> 40 | H39: =IF(C39="","",IF(G39="","Thiếu thông tin",IF(G39<6,"Trẻ em",IF(G39<23,"Học sinh / Sinh viên",IF(G39<60,"Đang đi làm","Nghỉ hưu"))))) -> Đang đi làm | J39: =IF(B39="","",IFERROR(INDEX('Hộ gia đình'!$B$2:$B$2000,MATCH(B39,'Hộ gia đình'!$A$2:$A$2000,0)),"Mã hộ không tồn tại")) -> 50 Lê Thanh Nghị | N39: Không | O39: Đang ở | P39: ở NN | Q39: Sổ cư dân | R39: Ghi chú cho thấy có thể không còn ở tổ – kiểm tra Tình trạng
A40: CD0039 | B40: H008 | C40: Trần Hoàng Long | E40: 34505 | F40: 1994 | G40: =IF(F40="","",YEAR(TODAY())-F40) -> 32 | H40: =IF(C40="","",IF(G40="","Thiếu thông tin",IF(G40<6,"Trẻ em",IF(G40<23,"Học sinh / Sinh viên",IF(G40<60,"Đang đi làm","Nghỉ hưu"))))) -> Đang đi làm | J40: =IF(B40="","",IFERROR(INDEX('Hộ gia đình'!$B$2:$B$2000,MATCH(B40,'Hộ gia đình'!$A$2:$A$2000,0)),"Mã hộ không tồn tại")) -> 50 Lê Thanh Nghị | N40: Không | O40: Đang ở | P40: ở NN | Q40: Sổ cư dân | R40: Ghi chú cho thấy có thể không còn ở tổ – kiểm tra Tình trạng
...

Sheet Biến động
A1: Ngày | B1: Loại | C1: Mã CD | D1: Họ và tên | E1: Mã hộ | F1: Nội dung | G1: Người cập nhật
D2: =IF(C2="","",IFERROR(INDEX('Cư dân'!$C$2:$C$2000,MATCH(C2,'Cư dân'!$A$2:$A$2000,0)),"Mã không tồn tại"))
D3: =IF(C3="","",IFERROR(INDEX('Cư dân'!$C$2:$C$2000,MATCH(C3,'Cư dân'!$A$2:$A$2000,0)),"Mã không tồn tại"))
D4: =IF(C4="","",IFERROR(INDEX('Cư dân'!$C$2:$C$2000,MATCH(C4,'Cư dân'!$A$2:$A$2000,0)),"Mã không tồn tại"))
D5: =IF(C5="","",IFERROR(INDEX('Cư dân'!$C$2:$C$2000,MATCH(C5,'Cư dân'!$A$2:$A$2000,0)),"Mã không tồn tại"))
D6: =IF(C6="","",IFERROR(INDEX('Cư dân'!$C$2:$C$2000,MATCH(C6,'Cư dân'!$A$2:$A$2000,0)),"Mã không tồn tại"))
D7: =IF(C7="","",IFERROR(INDEX('Cư dân'!$C$2:$C$2000,MATCH(C7,'Cư dân'!$A$2:$A$2000,0)),"Mã không tồn tại"))
D8: =IF(C8="","",IFERROR(INDEX('Cư dân'!$C$2:$C$2000,MATCH(C8,'Cư dân'!$A$2:$A$2000,0)),"Mã không tồn tại"))
D9: =IF(C9="","",IFERROR(INDEX('Cư dân'!$C$2:$C$2000,MATCH(C9,'Cư dân'!$A$2:$A$2000,0)),"Mã không tồn tại"))
D10: =IF(C10="","",IFERROR(INDEX('Cư dân'!$C$2:$C$2000,MATCH(C10,'Cư dân'!$A$2:$A$2000,0)),"Mã không tồn tại"))
D11: =IF(C11="","",IFERROR(INDEX('Cư dân'!$C$2:$C$2000,MATCH(C11,'Cư dân'!$A$2:$A$2000,0)),"Mã không tồn tại"))
D12: =IF(C12="","",IFERROR(INDEX('Cư dân'!$C$2:$C$2000,MATCH(C12,'Cư dân'!$A$2:$A$2000,0)),"Mã không tồn tại"))
D13: =IF(C13="","",IFERROR(INDEX('Cư dân'!$C$2:$C$2000,MATCH(C13,'Cư dân'!$A$2:$A$2000,0)),"Mã không tồn tại"))
... D499: =IF(C499="","",IFERROR(INDEX('Cư dân'!$C$2:$C$2000,MATCH(C499,'Cư dân'!$A$2:$A$2000,0)),"Mã không tồn tại"))
